
<mujoco>
  <option timestep="0.005" gravity="0 0 -9.81"/>
  
  <asset>
    <texture name="grid" type="2d" builtin="checker" rgb1=".1 .2 .3" rgb2=".2 .3 .4" width="300" height="300"/>
    <material name="ground" texture="grid" texrepeat="5 5" reflectance=".2"/>
  </asset>
  
  <worldbody>
    <!-- Ground plane -->
    <geom name="floor" type="plane" size="5 5 0.1" material="ground"/>
    
    <!-- Light -->
    <light pos="0 2 5" dir="0 0 -1" directional="true"/>
    
    <!-- A red ball you can push around -->
    <body name="ball" pos="0 0 1">
      <joint name="ball_slide" type="slide" axis="1 0 0" limited="false"/>
      <joint name="ball_slide2" type="slide" axis="0 1 0" limited="false"/>
      <joint name="ball_spin" type="ball" limited="false"/>
      <geom name="ball_geom" type="sphere" size="0.5" rgba="1 0 0 1" mass="1"/>
    </body>
    
    <!-- A green block -->
    <body name="block" pos="1 1 0.25">
      <joint name="block_slide" type="slide" axis="1 0 0" limited="false"/>
      <joint name="block_slide2" type="slide" axis="0 1 0" limited="false"/>
      <geom name="block_geom" type="box" size="0.3 0.3 0.25" rgba="0 1 0 1" mass="2"/>
    </body>
    
    <!-- A blue ramp to slide things down -->
    <body name="ramp" pos="-1 -1 0">
      <geom name="ramp_geom" type="box" size="1 0.5 0.1" rgba="0 0 1 1" euler="0.3 0 0"/>
    </body>
  </worldbody>
  
  <actuator>
    <!-- Motors to control the ball (optional) -->
    <motor name="push_x" joint="ball_slide" gear="10" ctrlrange="-1 1"/>
    <motor name="push_y" joint="ball_slide2" gear="10" ctrlrange="-1 1"/>
  </actuator>
  
  <contact>
    <pair geom1="ball_geom" geom2="floor" solref="0.02 1"/>
  </contact>
</mujoco>
